Workbook

Sheet copy of data
A1: Person | B1: Age | C1: Gender | D1: Own Home | E1: Married | F1: Close | G1: Salary | H1: Children | I1: History | J1: Catalogs | K1: Region | L1: State | M1: City | N1: First Purchase | O1: Amount Spent
A2: 1 | B2: 1 | C2: 0 | D2: 0 | E2: 0 | F2: 1 | G2: 16400 | H2: 1 | I2: 1 | J2: 12 | K2: South | L2: Florida | M2: Orlando | N2: 39744 | O2: 218
A3: 2 | B3: 2 | C3: 0 | D3: 1 | E3: 1 | F3: 0 | G3: 108100 | H3: 3 | I3: 3 | J3: 18 | K3: Midwest | L3: Illinois | M3: Chicago | N3: 38862 | O3: 2632
A4: 3 | B4: 2 | C4: 1 | D4: 1 | E4: 1 | F4: 1 | G4: 97300 | H4: 1 | I4: NA | J4: 12 | K4: South | L4: Florida | M4: Orlando | N4: 41139 | O4: 3048
A5: 4 | B5: 3 | C5: 1 | D5: 1 | E5: 1 | F5: 1 | G5: 26800 | H5: 0 | I5: 1 | J5: 12 | K5: East | L5: Ohio | M5: Cleveland | N5: 40173 | O5: 435
A6: 5 | B6: 1 | C6: 1 | D6: 0 | E6: 0 | F6: 1 | G6: 11200 | H6: 0 | I6: NA | J6: 6 | K6: Midwest | L6: Illinois | M6: Chicago | N6: 41125 | O6: 106
A7: 6 | B7: 2 | C7: 0 | D7: 0 | E7: 0 | F7: 1 | G7: 42800 | H7: 0 | I7: 2 | J7: 12 | K7: West | L7: Arizona | M7: Phoenix | N7: 40241 | O7: 759
A8: 7 | B8: 2 | C8: 0 | D8: 0 | E8: 0 | F8: 1 | G8: 34700 | H8: 0 | I8: NA | J8: 18 | K8: Midwest | L8: Kansas | M8: Kansas City | N8: 41071 | O8: 1615
A9: 8 | B9: 3 | C9: 0 | D9: 1 | E9: 1 | F9: 0 | G9: 80000 | H9: 0 | I9: 3 | J9: 6 | K9: West | L9: California | M9: San Francisco | N9: 38946 | O9: 1985
A10: 9 | B10: 2 | C10: 1 | D10: 1 | E10: 0 | F10: 1 | G10: 60300 | H10: 0 | I10: NA | J10: 24 | K10: Midwest | L10: Illinois | M10: Chicago | N10: 41058 | O10: 2091
A11: 10 | B11: 3 | C11: 1 | D11: 1 | E11: 1 | F11: 0 | G11: 62300 | H11: 0 | I11: 3 | J11: 24 | K11: South | L11: Florida | M11: Orlando | N11: 39608 | O11: 2644
A12: 11 | B12: 2 | C12: 1 | D12: 0 | E12: 1 | F12: 1 | G12: 94200 | H12: 1 | I12: 3 | J12: 18 | K12: East | L12: New York | M12: Buffalo | N12: 39565 | O12: 1211
A13: 12 | B13: 2 | C13: 1 | D13: 1 | E13: 1 | F13: 0 | G13: 73800 | H13: 0 | I13: 3 | J13: 24 | K13: West | L13: Utah | M13: Salt Lake City | N13: 39673 | O13: 3120
A14: 13 | B14: 2 | C14: 1 | D14: 1 | E14: 0 | F14: 1 | G14: 45900 | H14: 2 | I14: 1 | J14: 12 | K14: South | L14: Louisiana | M14: New Orleans | N14: 39601 | O14: 416
A15: 14 | B15: 2 | C15: 1 | D15: 0 | E15: 0 | F15: 0 | G15: 52600 | H15: 1 | I15: NA | J15: 18 | K15: East | L15: New York | M15: Buffalo | N15: 41007 | O15: 1773
A16: 15 | B16: 2 | C16: 0 | D16: 1 | E16: 1 | F16: 1 | G16: 82200 | H16: 1 | I16: NA | J16: 12 | K16: West | L16: California | M16: Los Angeles | N16: 41014 | O16: 1517
A17: 16 | B17: 2 | C17: 0 | D17: 1 | E17: 1 | F17: 1 | G17: 76700 | H17: 2 | I17: 2 | J17: 6 | K17: East | L17: Pennsylvania | M17: Philadelphia | N17: 40022 | O17: 534
A18: 17 | B18: 2 | C18: 0 | D18: 1 | E18: 1 | F18: 1 | G18: 79400 | H18: 3 | I18: 1 | J18: 6 | K18: South | L18: Tennessee | M18: Memphis | N18: 40969 | O18: 200
A19: 18 | B19: 2 | C19: 1 | D19: 1 | E19: 1 | F19: 1 | G19: 66900 | H19: 0 | I19: 3 | J19: 12 | K19: West | L19: Washington | M19: Seattle | N19: 38849 | O19: 1220
A20: 19 | B20: 1 | C20: 0 | D20: 0 | E20: 0 | F20: 1 | G20: 12400 | H20: 1 | I20: NA | J20: 12 | K20: South | L20: Florida | M20: Miami | N20: 41022 | O20: 229
A21: 20 | B21: 1 | C21: 1 | D21: 0 | E21: 1 | F21: 1 | G21: 52600 | H21: 1 | I21: 2 | J21: 12 | K21: South | L21: Louisiana | M21: New Orleans | N21: 39596 | O21: 1052
A22: 21 | B22: 3 | C22: 0 | D22: 1 | E22: 0 | F22: 0 | G22: 28300 | H22: 0 | I22: 2 | J22: 24 | K22: Midwest | L22: Missouri | M22: St. Louis | N22: 39016 | O22: 933
A23: 22 | B23: 2 | C23: 1 | D23: 1 | E23: 0 | F23: 0 | G23: 53900 | H23: 0 | I23: NA | J23: 12 | K23: South | L23: Texas | M23: Houston | N23: 40938 | O23: 1186
A24: 23 | B24: 3 | C24: 0 | D24: 0 | E24: 0 | F24: 1 | G24: 28900 | H24: 0 | I24: 1 | J24: 12 | K24: South | L24: Tennessee | M24: Memphis | N24: 39456 | O24: 830
A25: 24 | B25: 1 | C25: 0 | D25: 0 | E25: 0 | F25: 1 | G25: 15900 | H25: 0 | I25: NA | J25: 18 | K25: East | L25: Ohio | M25: Cleveland | N25: 41073 | O25: 406
A26: 25 | B26: 2 | C26: 1 | D26: 0 | E26: 0 | F26: 1 | G26: 50700 | H26: 3 | I26: 1 | J26: 6 | K26: Midwest | L26: Ohio | M26: Cincinnati | N26: 40688 | O26: 157
A27: 26 | B27: 1 | C27: 1 | D27: 0 | E27: 0 | F27: 0 | G27: 17800 | H27: 1 | I27: NA | J27: 18 | K27: South | L27: Florida | M27: Miami | N27: 41048 | O27: 589
A28: 27 | B28: 2 | C28: 0 | D28: 1 | E28: 0 | F28: 1 | G28: 51300 | H28: 0 | I28: 2 | J28: 24 | K28: West | L28: California | M28: Los Angeles | N28: 40903 | O28: 1424
A29: 28 | B29: 3 | C29: 0 | D29: 1 | E29: 1 | F29: 1 | G29: 74400 | H29: 0 | I29: 3 | J29: 18 | K29: East | L29: New York | M29: Buffalo | N29: 39239 | O29: 2479
A30: 29 | B30: 2 | C30: 0 | D30: 1 | E30: 1 | F30: 1 | G30: 88200 | H30: 0 | I30: NA | J30: 24 | K30: South | L30: Florida | M30: Miami | N30: 40978 | O30: 2749
A31: 30 | B31: 2 | C31: 1 | D31: 1 | E31: 1 | F31: 0 | G31: 79000 | H31: 1 | I31: 3 | J31: 18 | K31: East | L31: Massachusetts | M31: Boston | N31: 40271 | O31: 2279
A32: 31 | B32: 2 | C32: 0 | D32: 1 | E32: 0 | F32: 0 | G32: 55200 | H32: 0 | I32: 3 | J32: 18 | K32: East | L32: New York | M32: New York | N32: 39326 | O32: 1714
A33: 32 | B33: 2 | C33: 1 | D33: 1 | E33: 1 | F33: 1 | G33: 95800 | H33: 3 | I33: 1 | J33: 12 | K33: Midwest | L33: Missouri | M33: St. Louis | N33: 40210 | O33: 678
A34: 33 | B34: 1 | C34: 0 | D34: 0 | E34: 0 | F34: 0 | G34: 13700 | H34: 2 | I34: NA | J34: 24 | K34: West | L34: Arizona | M34: Phoenix | N34: 41115 | O34: 414
A35: 34 | B35: 2 | C35: 0 | D35: 1 | E35: 0 | F35: 1 | G35: 41300 | H35: 1 | I35: NA | J35: 18 | K35: East | L35: New York | M35: New York | N35: 41080 | O35: 932
A36: 35 | B36: 2 | C36: 1 | D36: 1 | E36: 0 | F36: 0 | G36: 65400 | H36: 1 | I36: 3 | J36: 12 | K36: South | L36: Florida | M36: Orlando | N36: 39564 | O36: 2290
A37: 36 | B37: 1 | C37: 0 | D37: 1 | E37: 0 | F37: 0 | G37: 29600 | H37: 3 | I37: NA | J37: 12 | K37: East | L37: Ohio | M37: Cleveland | N37: 41059 | O37: 774
A38: 37 | B38: 1 | C38: 1 | D38: 0 | E38: 1 | F38: 1 | G38: 49800 | H38: 0 | I38: 2 | J38: 12 | K38: Midwest | L38: Ohio | M38: Cincinnati | N38: 40641 | O38: 827
A39: 38 | B39: 2 | C39: 1 | D39: 1 | E39: 0 | F39: 1 | G39: 73700 | H39: 1 | I39: 2 | J39: 12 | K39: South | L39: Texas | M39: Houston | N39: 40405 | O39: 1274
A40: 39 | B40: 3 | C40: 0 | D40: 1 | E40: 0 | F40: 1 | G40: 39900 | H40: 0 | I40: NA | J40: 6 | K40: East | L40: New York | M40: New York | N40: 40938 | O40: 619
...

Sheet EditedData
A1: Person | B1: Age | C1: Gender | D1: Own Home | E1: Married | F1: MARRIED? | G1: Close | H1: Salary | I1: Salary Grade | J1: Children | K1: History | L1: Catalogs | M1: Region | N1: State | O1: City | P1: First Purchase | Q1: Amount Spent
A2: 625 | B2: 2 | C2: 0 | D2: 1 | E2: 1 | F2: =IF(E2=0,"NO", IF(E2=1,"YES")) -> YES | G2: 1 | H2: 63700 | I2: =VLOOKUP(H2,vlookup!$A$2:$B$5,2,TRUE) -> 2 | J2: 3 | K2: 1 | L2: 12 | M2: East | N2: Massachusetts | O2: Boston | P2: 38744 | Q2: 364
A3: 52 | B3: 2 | C3: 1 | D3: 1 | E3: 0 | F3: =IF(E3=0,"NO", IF(E3=1,"YES")) -> NO | G3: 1 | H3: 56700 | I3: =VLOOKUP(H3,vlookup!$A$2:$B$5,2,TRUE) -> 2 | J3: 2 | K3: 1 | L3: 18 | M3: East | N3: Massachusetts | O3: Boston | P3: 38735 | Q3: 536
A4: 159 | B4: 2 | C4: 1 | D4: 1 | E4: 1 | F4: =IF(E4=0,"NO", IF(E4=1,"YES")) -> YES | G4: 1 | H4: 63300 | I4: =VLOOKUP(H4,vlookup!$A$2:$B$5,2,TRUE) -> 2 | J4: 2 | K4: NA | L4: 6 | M4: East | N4: Massachusetts | O4: Boston | P4: 41005 | Q4: 633
A5: 30 | B5: 2 | C5: 1 | D5: 1 | E5: 1 | F5: =IF(E5=0,"NO", IF(E5=1,"YES")) -> YES | G5: 0 | H5: 79000 | I5: =VLOOKUP(H5,vlookup!$A$2:$B$5,2,TRUE) -> 2 | J5: 1 | K5: 3 | L5: 18 | M5: East | N5: Massachusetts | O5: Boston | P5: 40271 | Q5: 2279
A6: 209 | B6: 1 | C6: 0 | D6: 0 | E6: 1 | F6: =IF(E6=0,"NO", IF(E6=1,"YES")) -> YES | G6: 1 | H6: 61000 | I6: =VLOOKUP(H6,vlookup!$A$2:$B$5,2,TRUE) -> 2 | J6: 1 | K6: NA | L6: 18 | M6: East | N6: Massachusetts | O6: Boston | P6: 40954 | Q6: 1611
A7: 317 | B7: 3 | C7: 1 | D7: 0 | E7: 0 | F7: =IF(E7=0,"NO", IF(E7=1,"YES")) -> NO | G7: 1 | H7: 32400 | I7: =VLOOKUP(H7,vlookup!$A$2:$B$5,2,TRUE) -> 1 | J7: 1 | K7: 1 | L7: 12 | M7: East | N7: Massachusetts | O7: Boston | P7: 39742 | Q7: 515
A8: 346 | B8: 2 | C8: 0 | D8: 1 | E8: 1 | F8: =IF(E8=0,"NO", IF(E8=1,"YES")) -> YES | G8: 1 | H8: 70900 | I8: =VLOOKUP(H8,vlookup!$A$2:$B$5,2,TRUE) -> 2 | J8: 1 | K8: 2 | L8: 12 | M8: East | N8: Massachusetts | O8: Boston | P8: 39897 | Q8: 794
A9: 398 | B9: 2 | C9: 0 | D9: 1 | E9: 0 | F9: =IF(E9=0,"NO", IF(E9=1,"YES")) -> NO | G9: 1 | H9: 60200 | I9: =VLOOKUP(H9,vlookup!$A$2:$B$5,2,TRUE) -> 2 | J9: 1 | K9: NA | L9: 12 | M9: East | N9: Massachusetts | O9: Boston | P9: 40967 | Q9: 1748
A10: 485 | B10: 2 | C10: 1 | D10: 1 | E10: 1 | F10: =IF(E10=0,"NO", IF(E10=1,"YES")) -> YES | G10: 0 | H10: 77800 | I10: =VLOOKUP(H10,vlookup!$A$2:$B$5,2,TRUE) -> 2 | J10: 1 | K10: 3 | L10: 18 | M10: East | N10: Massachusetts | O10: Boston | P10: 38865 | Q10: 1813
A11: 557 | B11: 1 | C11: 0 | D11: 0 | E11: 0 | F11: =IF(E11=0,"NO", IF(E11=1,"YES")) -> NO | G11: 0 | H11: 21100 | I11: =VLOOKUP(H11,vlookup!$A$2:$B$5,2,TRUE) -> 1 | J11: 1 | K11: 1 | L11: 6 | M11: East | N11: Massachusetts | O11: Boston | P11: 39031 | Q11: 470
A12: 617 | B12: 2 | C12: 0 | D12: 1 | E12: 1 | F12: =IF(E12=0,"NO", IF(E12=1,"YES")) -> YES | G12: 1 | H12: 105300 | I12: =VLOOKUP(H12,vlookup!$A$2:$B$5,2,TRUE) -> 3 | J12: 1 | K12: NA | L12: 24 | M12: East | N12: Massachusetts | O12: Boston | P12: 40992 | Q12: 3360
A13: 698 | B13: 2 | C13: 1 | D13: 0 | E13: 0 | F13: =IF(E13=0,"NO", IF(E13=1,"YES")) -> NO | G13: 1 | H13: 53900 | I13: =VLOOKUP(H13,vlookup!$A$2:$B$5,2,TRUE) -> 2 | J13: 1 | K13: 2 | L13: 6 | M13: East | N13: Massachusetts | O13: Boston | P13: 40810 | Q13: 735
A14: 771 | B14: 2 | C14: 1 | D14: 1 | E14: 1 | F14: =IF(E14=0,"NO", IF(E14=1,"YES")) -> YES | G14: 1 | H14: 88700 | I14: =VLOOKUP(H14,vlookup!$A$2:$B$5,2,TRUE) -> 2 | J14: 1 | K14: NA | L14: 18 | M14: East | N14: Massachusetts | O14: Boston | P14: 40996 | Q14: 2448
A15: 828 | B15: 2 | C15: 0 | D15: 0 | E15: 1 | F15: =IF(E15=0,"NO", IF(E15=1,"YES")) -> YES | G15: 1 | H15: 66500 | I15: =VLOOKUP(H15,vlookup!$A$2:$B$5,2,TRUE) -> 2 | J15: 1 | K15: NA | L15: 24 | M15: East | N15: Massachusetts | O15: Boston | P15: 41029 | Q15: 1181
A16: 56 | B16: 3 | C16: 0 | D16: 1 | E16: 0 | F16: =IF(E16=0,"NO", IF(E16=1,"YES")) -> NO | G16: 0 | H16: 22000 | I16: =VLOOKUP(H16,vlookup!$A$2:$B$5,2,TRUE) -> 1 | J16: 0 | K16: 2 | L16: 12 | M16: East | N16: Massachusetts | O16: Boston | P16: 39025 | Q16: 736
A17: 78 | B17: 1 | C17: 0 | D17: 0 | E17: 1 | F17: =IF(E17=0,"NO", IF(E17=1,"YES")) -> YES | G17: 1 | H17: 79400 | I17: =VLOOKUP(H17,vlookup!$A$2:$B$5,2,TRUE) -> 2 | J17: 0 | K17: NA | L17: 6 | M17: East | N17: Massachusetts | O17: Boston | P17: 41030 | Q17: 1175
A18: 142 | B18: 3 | C18: 1 | D18: 0 | E18: 0 | F18: =IF(E18=0,"NO", IF(E18=1,"YES")) -> NO | G18: 1 | H18: 56300 | I18: =VLOOKUP(H18,vlookup!$A$2:$B$5,2,TRUE) -> 2 | J18: 0 | K18: 2 | L18: 6 | M18: East | N18: Massachusetts | O18: Boston | P18: 39524 | Q18: 873
A19: 181 | B19: 1 | C19: 1 | D19: 0 | E19: 0 | F19: =IF(E19=0,"NO", IF(E19=1,"YES")) -> NO | G19: 1 | H19: 25800 | I19: =VLOOKUP(H19,vlookup!$A$2:$B$5,2,TRUE) -> 1 | J19: 0 | K19: NA | L19: 6 | M19: East | N19: Massachusetts | O19: Boston | P19: 41022 | Q19: 451
A20: 223 | B20: 3 | C20: 0 | D20: 1 | E20: 1 | F20: =IF(E20=0,"NO", IF(E20=1,"YES")) -> YES | G20: 0 | H20: 79300 | I20: =VLOOKUP(H20,vlookup!$A$2:$B$5,2,TRUE) -> 2 | J20: 0 | K20: NA | L20: 12 | M20: East | N20: Massachusetts | O20: Boston | P20: 40975 | Q20: 2047
A21: 285 | B21: 1 | C21: 1 | D21: 0 | E21: 0 | F21: =IF(E21=0,"NO", IF(E21=1,"YES")) -> NO | G21: 0 | H21: 13900 | I21: =VLOOKUP(H21,vlookup!$A$2:$B$5,2,TRUE) -> 1 | J21: 0 | K21: NA | L21: 24 | M21: East | N21: Massachusetts | O21: Boston | P21: 40946 | Q21: 570
A22: 287 | B22: 3 | C22: 0 | D22: 0 | E22: 1 | F22: =IF(E22=0,"NO", IF(E22=1,"YES")) -> YES | G22: 0 | H22: 72200 | I22: =VLOOKUP(H22,vlookup!$A$2:$B$5,2,TRUE) -> 2 | J22: 0 | K22: 3 | L22: 24 | M22: East | N22: Massachusetts | O22: Boston | P22: 40141 | Q22: 3069
A23: 326 | B23: 2 | C23: 1 | D23: 0 | E23: 0 | F23: =IF(E23=0,"NO", IF(E23=1,"YES")) -> NO | G23: 1 | H23: 41200 | I23: =VLOOKUP(H23,vlookup!$A$2:$B$5,2,TRUE) -> 1 | J23: 0 | K23: 2 | L23: 12 | M23: East | N23: Massachusetts | O23: Boston | P23: 39216 | Q23: 841
A24: 338 | B24: 2 | C24: 1 | D24: 1 | E24: 0 | F24: =IF(E24=0,"NO", IF(E24=1,"YES")) -> NO | G24: 1 | H24: 55600 | I24: =VLOOKUP(H24,vlookup!$A$2:$B$5,2,TRUE) -> 2 | J24: 0 | K24: NA | L24: 12 | M24: East | N24: Massachusetts | O24: Boston | P24: 40981 | Q24: 952
A25: 397 | B25: 3 | C25: 0 | D25: 1 | E25: 1 | F25: =IF(E25=0,"NO", IF(E25=1,"YES")) -> YES | G25: 1 | H25: 74700 | I25: =VLOOKUP(H25,vlookup!$A$2:$B$5,2,TRUE) -> 2 | J25: 0 | K25: 3 | L25: 12 | M25: East | N25: Massachusetts | O25: Boston | P25: 39699 | Q25: 1699
A26: 509 | B26: 2 | C26: 1 | D26: 1 | E26: 1 | F26: =IF(E26=0,"NO", IF(E26=1,"YES")) -> YES | G26: 1 | H26: 82400 | I26: =VLOOKUP(H26,vlookup!$A$2:$B$5,2,TRUE) -> 2 | J26: 0 | K26: 3 | L26: 18 | M26: East | N26: Massachusetts | O26: Boston | P26: 41131 | Q26: 1779
A27: 568 | B27: 2 | C27: 1 | D27: 1 | E27: 1 | F27: =IF(E27=0,"NO", IF(E27=1,"YES")) -> YES | G27: 1 | H27: 90300 | I27: =VLOOKUP(H27,vlookup!$A$2:$B$5,2,TRUE) -> 2 | J27: 0 | K27: 3 | L27: 24 | M27: East | N27: Massachusetts | O27: Boston | P27: 40648 | Q27: 1944
A28: 665 | B28: 3 | C28: 1 | D28: 1 | E28: 1 | F28: =IF(E28=0,"NO", IF(E28=1,"YES")) -> YES | G28: 0 | H28: 80700 | I28: =VLOOKUP(H28,vlookup!$A$2:$B$5,2,TRUE) -> 2 | J28: 0 | K28: NA | L28: 18 | M28: East | N28: Massachusetts | O28: Boston | P28: 41048 | Q28: 3034
A29: 685 | B29: 3 | C29: 1 | D29: 1 | E29: 1 | F29: =IF(E29=0,"NO", IF(E29=1,"YES")) -> YES | G29: 0 | H29: 65500 | I29: =VLOOKUP(H29,vlookup!$A$2:$B$5,2,TRUE) -> 2 | J29: 0 | K29: 3 | L29: 24 | M29: East | N29: Massachusetts | O29: Boston | P29: 39050 | Q29: 1931
A30: 705 | B30: 3 | C30: 1 | D30: 0 | E30: 1 | F30: =IF(E30=0,"NO", IF(E30=1,"YES")) -> YES | G30: 1 | H30: 81800 | I30: =VLOOKUP(H30,vlookup!$A$2:$B$5,2,TRUE) -> 2 | J30: 0 | K30: 3 | L30: 6 | M30: East | N30: Massachusetts | O30: Boston | P30: 40389 | Q30: 919
A31: 731 | B31: 2 | C31: 1 | D31: 0 | E31: 0 | F31: =IF(E31=0,"NO", IF(E31=1,"YES")) -> NO | G31: 0 | H31: 59000 | I31: =VLOOKUP(H31,vlookup!$A$2:$B$5,2,TRUE) -> 2 | J31: 0 | K31: 3 | L31: 24 | M31: East | N31: Massachusetts | O31: Boston | P31: 40027 | Q31: 3044
A32: 911 | B32: 3 | C32: 0 | D32: 1 | E32: 1 | F32: =IF(E32=0,"NO", IF(E32=1,"YES")) -> YES | G32: 1 | H32: 62800 | I32: =VLOOKUP(H32,vlookup!$A$2:$B$5,2,TRUE) -> 2 | J32: 0 | K32: 3 | L32: 18 | M32: East | N32: Massachusetts | O32: Boston | P32: 40544 | Q32: 1403
A33: 939 | B33: 3 | C33: 1 | D33: 0 | E33: 1 | F33: =IF(E33=0,"NO", IF(E33=1,"YES")) -> YES | G33: 0 | H33: 23800 | I33: =VLOOKUP(H33,vlookup!$A$2:$B$5,2,TRUE) -> 1 | J33: 0 | K33: NA | L33: 12 | M33: East | N33: Massachusetts | O33: Boston | P33: 41020 | Q33: 428
A34: 947 | B34: 3 | C34: 0 | D34: 0 | E34: 1 | F34: =IF(E34=0,"NO", IF(E34=1,"YES")) -> YES | G34: 1 | H34: 71800 | I34: =VLOOKUP(H34,vlookup!$A$2:$B$5,2,TRUE) -> 2 | J34: 0 | K34: 3 | L34: 24 | M34: East | N34: Massachusetts | O34: Boston | P34: 39690 | Q34: 1946
A35: 949 | B35: 3 | C35: 1 | D35: 0 | E35: 1 | F35: =IF(E35=0,"NO", IF(E35=1,"YES")) -> YES | G35: 1 | H35: 71800 | I35: =VLOOKUP(H35,vlookup!$A$2:$B$5,2,TRUE) -> 2 | J35: 0 | K35: 3 | L35: 12 | M35: East | N35: Massachusetts | O35: Boston | P35: 40009 | Q35: 1389
A36: 951 | B36: 1 | C36: 0 | D36: 0 | E36: 1 | F36: =IF(E36=0,"NO", IF(E36=1,"YES")) -> YES | G36: 1 | H36: 61700 | I36: =VLOOKUP(H36,vlookup!$A$2:$B$5,2,TRUE) -> 2 | J36: 0 | K36: NA | L36: 12 | M36: East | N36: Massachusetts | O36: Boston | P36: 40945 | Q36: 1161
A37: 956 | B37: 3 | C37: 1 | D37: 1 | E37: 0 | F37: =IF(E37=0,"NO", IF(E37=1,"YES")) -> NO | G37: 1 | H37: 38700 | I37: =VLOOKUP(H37,vlookup!$A$2:$B$5,2,TRUE) -> 1 | J37: 0 | K37: NA | L37: 24 | M37: East | N37: Massachusetts | O37: Boston | P37: 41080 | Q37: 1506
A38: 957 | B38: 3 | C38: 0 | D38: 1 | E38: 0 | F38: =IF(E38=0,"NO", IF(E38=1,"YES")) -> NO | G38: 1 | H38: 11400 | I38: =VLOOKUP(H38,vlookup!$A$2:$B$5,2,TRUE) -> 1 | J38: 0 | K38: NA | L38: 6 | M38: East | N38: Massachusetts | O38: Boston | P38: 41083 | Q38: 258
A39: 72 | B39: 2 | C39: 1 | D39: 0 | E39: 1 | F39: =IF(E39=0,"NO", IF(E39=1,"YES")) -> YES | G39: 0 | H39: 72200 | I39: =VLOOKUP(H39,vlookup!$A$2:$B$5,2,TRUE) -> 2 | J39: 3 | K39: 2 | L39: 18 | M39: East | N39: New York | O39: Buffalo | P39: 40606 | Q39: 1811
A40: 250 | B40: 2 | C40: 1 | D40: 1 | E40: 0 | F40: =IF(E40=0,"NO", IF(E40=1,"YES")) -> NO | G40: 1 | H40: 49200 | I40: =VLOOKUP(H40,vlookup!$A$2:$B$5,2,TRUE) -> 1 | J40: 3 | K40: 1 | L40: 12 | M40: East | N40: New York | O40: Buffalo | P40: 41119 | Q40: 210
...

Sheet vlookup
A1: Salary | B1: Vlookup
A2: 0 | B2: 1
A3: 50001 | B3: 2
A4: 100001 | B4: 3
A5: 150001 | B5: 4
